/*
    An exception can be generated by one method and caught by another
 */
import java.util.Arrays;

class ExcTest {
    static void genException() {
        int[] nums = new int[4];

        // Exception generated here
        nums[4] = 5;
        System.out.println("This won't be displayed");
    }
}

public class ExcDemo2 {
    public static void main(String args[]) {

        // Exception caught here
        try {
            ExcTest.genException();
            System.out.println("This won't be displayed");
        } catch (ArrayIndexOutOfBoundsException e) {
            System.out.println("Array out of bounds exception");
        }
        System.out.println("After the catch statement");
    }
}
